[2025-04-18T13:40:40.144+0000] {local_task_job_runner.py:123} INFO - ::group::Pre task execution logs
[2025-04-18T13:40:40.196+0000] {taskinstance.py:2614} INFO - Dependencies all met for dep_context=non-requeueable deps ti=<TaskInstance: entsoe_etl_germany.extract_data scheduled__2024-03-04T00:00:00+00:00 [queued]>
[2025-04-18T13:40:40.243+0000] {taskinstance.py:2614} INFO - Dependencies all met for dep_context=requeueable deps ti=<TaskInstance: entsoe_etl_germany.extract_data scheduled__2024-03-04T00:00:00+00:00 [queued]>
[2025-04-18T13:40:40.245+0000] {taskinstance.py:2867} INFO - Starting attempt 2 of 2
[2025-04-18T13:40:42.046+0000] {taskinstance.py:2890} INFO - Executing <Task(PythonOperator): extract_data> on 2024-03-04 00:00:00+00:00
[2025-04-18T13:40:42.094+0000] {warnings.py:112} WARNING - /home/***/.local/lib/python3.12/site-packages/***/task/task_runner/standard_task_runner.py:70: DeprecationWarning: This process (pid=191) is multi-threaded, use of fork() may lead to deadlocks in the child.
  pid = os.fork()

[2025-04-18T13:40:42.103+0000] {standard_task_runner.py:72} INFO - Started process 194 to run task
[2025-04-18T13:40:42.129+0000] {standard_task_runner.py:104} INFO - Running: ['***', 'tasks', 'run', 'entsoe_etl_germany', 'extract_data', 'scheduled__2024-03-04T00:00:00+00:00', '--job-id', '709', '--raw', '--subdir', 'DAGS_FOLDER/entsoe_germany_dag.py', '--cfg-path', '/tmp/tmpq6nmm40x']
[2025-04-18T13:40:42.143+0000] {standard_task_runner.py:105} INFO - Job 709: Subtask extract_data
[2025-04-18T13:40:42.510+0000] {task_command.py:467} INFO - Running <TaskInstance: entsoe_etl_germany.extract_data scheduled__2024-03-04T00:00:00+00:00 [running]> on host c4a50f7f8da3
[2025-04-18T13:40:42.862+0000] {taskinstance.py:3134} INFO - Exporting env vars: AIRFLOW_CTX_DAG_OWNER='***' AIRFLOW_CTX_DAG_ID='entsoe_etl_germany' AIRFLOW_CTX_TASK_ID='extract_data' AIRFLOW_CTX_EXECUTION_DATE='2024-03-04T00:00:00+00:00' AIRFLOW_CTX_TRY_NUMBER='2' AIRFLOW_CTX_DAG_RUN_ID='scheduled__2024-03-04T00:00:00+00:00'
[2025-04-18T13:40:42.877+0000] {logging_mixin.py:190} INFO - Task instance is in running state
[2025-04-18T13:40:42.914+0000] {logging_mixin.py:190} INFO -  Previous state of the Task instance: queued
[2025-04-18T13:40:42.995+0000] {logging_mixin.py:190} INFO - Current task name:extract_data state:running start_date:2025-04-18 13:40:40.197456+00:00
[2025-04-18T13:40:43.003+0000] {logging_mixin.py:190} INFO - Dag name:entsoe_etl_germany and current dag run status:running
[2025-04-18T13:40:43.005+0000] {taskinstance.py:732} INFO - ::endgroup::
[2025-04-18T13:40:43.015+0000] {taskinstance.py:3313} ERROR - Task failed with exception
Traceback (most recent call last):
  File "/home/airflow/.local/lib/python3.12/site-packages/airflow/models/taskinstance.py", line 768, in _execute_task
    result = _execute_callable(context=context, **execute_callable_kwargs)
             ^^^^^^^^^^^^^^^^^^^^^^^^^^^^^^^^^^^^^^^^^^^^^^^^^^^^^^^^^^^^^
  File "/home/airflow/.local/lib/python3.12/site-packages/airflow/models/taskinstance.py", line 734, in _execute_callable
    return ExecutionCallableRunner(
           ^^^^^^^^^^^^^^^^^^^^^^^^
  File "/home/airflow/.local/lib/python3.12/site-packages/airflow/utils/operator_helpers.py", line 252, in run
    return self.func(*args, **kwargs)
           ^^^^^^^^^^^^^^^^^^^^^^^^^^
  File "/home/airflow/.local/lib/python3.12/site-packages/airflow/models/baseoperator.py", line 424, in wrapper
    return func(self, *args, **kwargs)
           ^^^^^^^^^^^^^^^^^^^^^^^^^^^
  File "/home/airflow/.local/lib/python3.12/site-packages/airflow/operators/python.py", line 238, in execute
    return_value = self.execute_callable()
                   ^^^^^^^^^^^^^^^^^^^^^^^
  File "/home/airflow/.local/lib/python3.12/site-packages/airflow/operators/python.py", line 256, in execute_callable
    return runner.run(*self.op_args, **self.op_kwargs)
           ^^^^^^^^^^^^^^^^^^^^^^^^^^^^^^^^^^^^^^^^^^^
  File "/home/airflow/.local/lib/python3.12/site-packages/airflow/utils/operator_helpers.py", line 252, in run
    return self.func(*args, **kwargs)
           ^^^^^^^^^^^^^^^^^^^^^^^^^^
  File "/opt/airflow/dags/etl/extract.py", line 38, in extract_data
    with open('mock_data/day_ahead_prices.xml', 'r') as f:
         ^^^^^^^^^^^^^^^^^^^^^^^^^^^^^^^^^^^^^^^^^^^
FileNotFoundError: [Errno 2] No such file or directory: 'mock_data/day_ahead_prices.xml'
[2025-04-18T13:40:43.256+0000] {logging_mixin.py:190} INFO - Task instance in failure state
[2025-04-18T13:40:43.270+0000] {logging_mixin.py:190} INFO - Task start:2025-04-18 13:40:40.197456+00:00 end:2025-04-18 13:40:43.187623+00:00 duration:2.990167
[2025-04-18T13:40:43.272+0000] {logging_mixin.py:190} INFO - Task:<Task(PythonOperator): extract_data> dag:<DAG: entsoe_etl_germany> dagrun:<DagRun entsoe_etl_germany @ 2024-03-04 00:00:00+00:00: scheduled__2024-03-04T00:00:00+00:00, state:running, queued_at: 2025-04-18 13:35:23.830848+00:00. externally triggered: False>
[2025-04-18T13:40:43.275+0000] {logging_mixin.py:190} INFO - Failure caused by [Errno 2] No such file or directory: 'mock_data/day_ahead_prices.xml'
[2025-04-18T13:40:43.276+0000] {taskinstance.py:1226} INFO - Marking task as FAILED. dag_id=entsoe_etl_germany, task_id=extract_data, run_id=scheduled__2024-03-04T00:00:00+00:00, execution_date=20240304T000000, start_date=20250418T134040, end_date=20250418T134043
[2025-04-18T13:40:43.909+0000] {taskinstance.py:341} INFO - ::group::Post task execution logs
[2025-04-18T13:40:44.064+0000] {standard_task_runner.py:124} ERROR - Failed to execute job 709 for task extract_data ([Errno 2] No such file or directory: 'mock_data/day_ahead_prices.xml'; 194)
Traceback (most recent call last):
  File "/home/airflow/.local/lib/python3.12/site-packages/airflow/task/task_runner/standard_task_runner.py", line 117, in _start_by_fork
    ret = args.func(args, dag=self.dag)
          ^^^^^^^^^^^^^^^^^^^^^^^^^^^^^
  File "/home/airflow/.local/lib/python3.12/site-packages/airflow/cli/cli_config.py", line 49, in command
    return func(*args, **kwargs)
           ^^^^^^^^^^^^^^^^^^^^^
  File "/home/airflow/.local/lib/python3.12/site-packages/airflow/utils/cli.py", line 116, in wrapper
    return f(*args, **kwargs)
           ^^^^^^^^^^^^^^^^^^
  File "/home/airflow/.local/lib/python3.12/site-packages/airflow/cli/commands/task_command.py", line 483, in task_run
    task_return_code = _run_task_by_selected_method(args, _dag, ti)
                       ^^^^^^^^^^^^^^^^^^^^^^^^^^^^^^^^^^^^^^^^^^^^
  File "/home/airflow/.local/lib/python3.12/site-packages/airflow/cli/commands/task_command.py", line 256, in _run_task_by_selected_method
    return _run_raw_task(args, ti)
           ^^^^^^^^^^^^^^^^^^^^^^^
  File "/home/airflow/.local/lib/python3.12/site-packages/airflow/cli/commands/task_command.py", line 341, in _run_raw_task
    return ti._run_raw_task(
           ^^^^^^^^^^^^^^^^^
  File "/home/airflow/.local/lib/python3.12/site-packages/airflow/utils/session.py", line 97, in wrapper
    return func(*args, session=session, **kwargs)
           ^^^^^^^^^^^^^^^^^^^^^^^^^^^^^^^^^^^^^^
  File "/home/airflow/.local/lib/python3.12/site-packages/airflow/models/taskinstance.py", line 3006, in _run_raw_task
    return _run_raw_task(
           ^^^^^^^^^^^^^^
  File "/home/airflow/.local/lib/python3.12/site-packages/airflow/models/taskinstance.py", line 274, in _run_raw_task
    TaskInstance._execute_task_with_callbacks(
  File "/home/airflow/.local/lib/python3.12/site-packages/airflow/models/taskinstance.py", line 3161, in _execute_task_with_callbacks
    result = self._execute_task(context, task_orig)
             ^^^^^^^^^^^^^^^^^^^^^^^^^^^^^^^^^^^^^^
  File "/home/airflow/.local/lib/python3.12/site-packages/airflow/models/taskinstance.py", line 3185, in _execute_task
    return _execute_task(self, context, task_orig)
           ^^^^^^^^^^^^^^^^^^^^^^^^^^^^^^^^^^^^^^^
  File "/home/airflow/.local/lib/python3.12/site-packages/airflow/models/taskinstance.py", line 768, in _execute_task
    result = _execute_callable(context=context, **execute_callable_kwargs)
             ^^^^^^^^^^^^^^^^^^^^^^^^^^^^^^^^^^^^^^^^^^^^^^^^^^^^^^^^^^^^^
  File "/home/airflow/.local/lib/python3.12/site-packages/airflow/models/taskinstance.py", line 734, in _execute_callable
    return ExecutionCallableRunner(
           ^^^^^^^^^^^^^^^^^^^^^^^^
  File "/home/airflow/.local/lib/python3.12/site-packages/airflow/utils/operator_helpers.py", line 252, in run
    return self.func(*args, **kwargs)
           ^^^^^^^^^^^^^^^^^^^^^^^^^^
  File "/home/airflow/.local/lib/python3.12/site-packages/airflow/models/baseoperator.py", line 424, in wrapper
    return func(self, *args, **kwargs)
           ^^^^^^^^^^^^^^^^^^^^^^^^^^^
  File "/home/airflow/.local/lib/python3.12/site-packages/airflow/operators/python.py", line 238, in execute
    return_value = self.execute_callable()
                   ^^^^^^^^^^^^^^^^^^^^^^^
  File "/home/airflow/.local/lib/python3.12/site-packages/airflow/operators/python.py", line 256, in execute_callable
    return runner.run(*self.op_args, **self.op_kwargs)
           ^^^^^^^^^^^^^^^^^^^^^^^^^^^^^^^^^^^^^^^^^^^
  File "/home/airflow/.local/lib/python3.12/site-packages/airflow/utils/operator_helpers.py", line 252, in run
    return self.func(*args, **kwargs)
           ^^^^^^^^^^^^^^^^^^^^^^^^^^
  File "/opt/airflow/dags/etl/extract.py", line 38, in extract_data
    with open('mock_data/day_ahead_prices.xml', 'r') as f:
         ^^^^^^^^^^^^^^^^^^^^^^^^^^^^^^^^^^^^^^^^^^^
FileNotFoundError: [Errno 2] No such file or directory: 'mock_data/day_ahead_prices.xml'
[2025-04-18T13:40:44.548+0000] {local_task_job_runner.py:266} INFO - Task exited with return code 1
[2025-04-18T13:40:45.371+0000] {local_task_job_runner.py:245} INFO - ::endgroup::
