[2025-04-18T13:39:56.392+0000] {local_task_job_runner.py:123} INFO - ::group::Pre task execution logs
[2025-04-18T13:39:56.486+0000] {taskinstance.py:2614} INFO - Dependencies all met for dep_context=non-requeueable deps ti=<TaskInstance: entsoe_etl_germany.extract_data scheduled__2024-02-24T00:00:00+00:00 [queued]>
[2025-04-18T13:39:56.512+0000] {taskinstance.py:2614} INFO - Dependencies all met for dep_context=requeueable deps ti=<TaskInstance: entsoe_etl_germany.extract_data scheduled__2024-02-24T00:00:00+00:00 [queued]>
[2025-04-18T13:39:56.515+0000] {taskinstance.py:2867} INFO - Starting attempt 1 of 2
[2025-04-18T13:40:04.806+0000] {taskinstance.py:2890} INFO - Executing <Task(PythonOperator): extract_data> on 2024-02-24 00:00:00+00:00
[2025-04-18T13:40:05.003+0000] {standard_task_runner.py:104} INFO - Running: ['***', 'tasks', 'run', 'entsoe_etl_germany', 'extract_data', 'scheduled__2024-02-24T00:00:00+00:00', '--job-id', '706', '--raw', '--subdir', 'DAGS_FOLDER/entsoe_germany_dag.py', '--cfg-path', '/tmp/tmpg73qxq5d']
[2025-04-18T13:40:05.036+0000] {standard_task_runner.py:105} INFO - Job 706: Subtask extract_data
[2025-04-18T13:40:05.021+0000] {warnings.py:112} WARNING - /home/***/.local/lib/python3.12/site-packages/***/task/task_runner/standard_task_runner.py:70: DeprecationWarning: This process (pid=152) is multi-threaded, use of fork() may lead to deadlocks in the child.
  pid = os.fork()

[2025-04-18T13:40:05.059+0000] {standard_task_runner.py:72} INFO - Started process 173 to run task
[2025-04-18T13:40:06.490+0000] {task_command.py:467} INFO - Running <TaskInstance: entsoe_etl_germany.extract_data scheduled__2024-02-24T00:00:00+00:00 [running]> on host c4a50f7f8da3
[2025-04-18T13:40:07.534+0000] {taskinstance.py:3134} INFO - Exporting env vars: AIRFLOW_CTX_DAG_OWNER='***' AIRFLOW_CTX_DAG_ID='entsoe_etl_germany' AIRFLOW_CTX_TASK_ID='extract_data' AIRFLOW_CTX_EXECUTION_DATE='2024-02-24T00:00:00+00:00' AIRFLOW_CTX_TRY_NUMBER='1' AIRFLOW_CTX_DAG_RUN_ID='scheduled__2024-02-24T00:00:00+00:00'
[2025-04-18T13:40:07.559+0000] {logging_mixin.py:190} INFO - Task instance is in running state
[2025-04-18T13:40:07.560+0000] {logging_mixin.py:190} INFO -  Previous state of the Task instance: queued
[2025-04-18T13:40:07.563+0000] {logging_mixin.py:190} INFO - Current task name:extract_data state:running start_date:2025-04-18 13:39:56.487080+00:00
[2025-04-18T13:40:07.568+0000] {logging_mixin.py:190} INFO - Dag name:entsoe_etl_germany and current dag run status:running
[2025-04-18T13:40:07.572+0000] {taskinstance.py:732} INFO - ::endgroup::
[2025-04-18T13:40:07.637+0000] {taskinstance.py:3313} ERROR - Task failed with exception
Traceback (most recent call last):
  File "/home/airflow/.local/lib/python3.12/site-packages/airflow/models/taskinstance.py", line 768, in _execute_task
    result = _execute_callable(context=context, **execute_callable_kwargs)
             ^^^^^^^^^^^^^^^^^^^^^^^^^^^^^^^^^^^^^^^^^^^^^^^^^^^^^^^^^^^^^
  File "/home/airflow/.local/lib/python3.12/site-packages/airflow/models/taskinstance.py", line 734, in _execute_callable
    return ExecutionCallableRunner(
           ^^^^^^^^^^^^^^^^^^^^^^^^
  File "/home/airflow/.local/lib/python3.12/site-packages/airflow/utils/operator_helpers.py", line 252, in run
    return self.func(*args, **kwargs)
           ^^^^^^^^^^^^^^^^^^^^^^^^^^
  File "/home/airflow/.local/lib/python3.12/site-packages/airflow/models/baseoperator.py", line 424, in wrapper
    return func(self, *args, **kwargs)
           ^^^^^^^^^^^^^^^^^^^^^^^^^^^
  File "/home/airflow/.local/lib/python3.12/site-packages/airflow/operators/python.py", line 238, in execute
    return_value = self.execute_callable()
                   ^^^^^^^^^^^^^^^^^^^^^^^
  File "/home/airflow/.local/lib/python3.12/site-packages/airflow/operators/python.py", line 256, in execute_callable
    return runner.run(*self.op_args, **self.op_kwargs)
           ^^^^^^^^^^^^^^^^^^^^^^^^^^^^^^^^^^^^^^^^^^^
  File "/home/airflow/.local/lib/python3.12/site-packages/airflow/utils/operator_helpers.py", line 252, in run
    return self.func(*args, **kwargs)
           ^^^^^^^^^^^^^^^^^^^^^^^^^^
  File "/opt/airflow/dags/etl/extract.py", line 38, in extract_data
    with open('mock_data/day_ahead_prices.xml', 'r') as f:
         ^^^^^^^^^^^^^^^^^^^^^^^^^^^^^^^^^^^^^^^^^^^
FileNotFoundError: [Errno 2] No such file or directory: 'mock_data/day_ahead_prices.xml'
[2025-04-18T13:40:08.014+0000] {logging_mixin.py:190} INFO - Task instance in failure state
[2025-04-18T13:40:08.019+0000] {logging_mixin.py:190} INFO - Task start:2025-04-18 13:39:56.487080+00:00 end:2025-04-18 13:40:08.010760+00:00 duration:11.52368
[2025-04-18T13:40:08.020+0000] {logging_mixin.py:190} INFO - Task:<Task(PythonOperator): extract_data> dag:<DAG: entsoe_etl_germany> dagrun:<DagRun entsoe_etl_germany @ 2024-02-24 00:00:00+00:00: scheduled__2024-02-24T00:00:00+00:00, state:running, queued_at: 2025-04-18 13:27:38.442489+00:00. externally triggered: False>
[2025-04-18T13:40:08.021+0000] {logging_mixin.py:190} INFO - Failure caused by [Errno 2] No such file or directory: 'mock_data/day_ahead_prices.xml'
[2025-04-18T13:40:08.023+0000] {taskinstance.py:1226} INFO - Marking task as UP_FOR_RETRY. dag_id=entsoe_etl_germany, task_id=extract_data, run_id=scheduled__2024-02-24T00:00:00+00:00, execution_date=20240224T000000, start_date=20250418T133956, end_date=20250418T134008
[2025-04-18T13:40:09.148+0000] {taskinstance.py:341} INFO - ::group::Post task execution logs
[2025-04-18T13:40:09.178+0000] {standard_task_runner.py:124} ERROR - Failed to execute job 706 for task extract_data ([Errno 2] No such file or directory: 'mock_data/day_ahead_prices.xml'; 173)
Traceback (most recent call last):
  File "/home/airflow/.local/lib/python3.12/site-packages/airflow/task/task_runner/standard_task_runner.py", line 117, in _start_by_fork
    ret = args.func(args, dag=self.dag)
          ^^^^^^^^^^^^^^^^^^^^^^^^^^^^^
  File "/home/airflow/.local/lib/python3.12/site-packages/airflow/cli/cli_config.py", line 49, in command
    return func(*args, **kwargs)
           ^^^^^^^^^^^^^^^^^^^^^
  File "/home/airflow/.local/lib/python3.12/site-packages/airflow/utils/cli.py", line 116, in wrapper
    return f(*args, **kwargs)
           ^^^^^^^^^^^^^^^^^^
  File "/home/airflow/.local/lib/python3.12/site-packages/airflow/cli/commands/task_command.py", line 483, in task_run
    task_return_code = _run_task_by_selected_method(args, _dag, ti)
                       ^^^^^^^^^^^^^^^^^^^^^^^^^^^^^^^^^^^^^^^^^^^^
  File "/home/airflow/.local/lib/python3.12/site-packages/airflow/cli/commands/task_command.py", line 256, in _run_task_by_selected_method
    return _run_raw_task(args, ti)
           ^^^^^^^^^^^^^^^^^^^^^^^
  File "/home/airflow/.local/lib/python3.12/site-packages/airflow/cli/commands/task_command.py", line 341, in _run_raw_task
    return ti._run_raw_task(
           ^^^^^^^^^^^^^^^^^
  File "/home/airflow/.local/lib/python3.12/site-packages/airflow/utils/session.py", line 97, in wrapper
    return func(*args, session=session, **kwargs)
           ^^^^^^^^^^^^^^^^^^^^^^^^^^^^^^^^^^^^^^
  File "/home/airflow/.local/lib/python3.12/site-packages/airflow/models/taskinstance.py", line 3006, in _run_raw_task
    return _run_raw_task(
           ^^^^^^^^^^^^^^
  File "/home/airflow/.local/lib/python3.12/site-packages/airflow/models/taskinstance.py", line 274, in _run_raw_task
    TaskInstance._execute_task_with_callbacks(
  File "/home/airflow/.local/lib/python3.12/site-packages/airflow/models/taskinstance.py", line 3161, in _execute_task_with_callbacks
    result = self._execute_task(context, task_orig)
             ^^^^^^^^^^^^^^^^^^^^^^^^^^^^^^^^^^^^^^
  File "/home/airflow/.local/lib/python3.12/site-packages/airflow/models/taskinstance.py", line 3185, in _execute_task
    return _execute_task(self, context, task_orig)
           ^^^^^^^^^^^^^^^^^^^^^^^^^^^^^^^^^^^^^^^
  File "/home/airflow/.local/lib/python3.12/site-packages/airflow/models/taskinstance.py", line 768, in _execute_task
    result = _execute_callable(context=context, **execute_callable_kwargs)
             ^^^^^^^^^^^^^^^^^^^^^^^^^^^^^^^^^^^^^^^^^^^^^^^^^^^^^^^^^^^^^
  File "/home/airflow/.local/lib/python3.12/site-packages/airflow/models/taskinstance.py", line 734, in _execute_callable
    return ExecutionCallableRunner(
           ^^^^^^^^^^^^^^^^^^^^^^^^
  File "/home/airflow/.local/lib/python3.12/site-packages/airflow/utils/operator_helpers.py", line 252, in run
    return self.func(*args, **kwargs)
           ^^^^^^^^^^^^^^^^^^^^^^^^^^
  File "/home/airflow/.local/lib/python3.12/site-packages/airflow/models/baseoperator.py", line 424, in wrapper
    return func(self, *args, **kwargs)
           ^^^^^^^^^^^^^^^^^^^^^^^^^^^
  File "/home/airflow/.local/lib/python3.12/site-packages/airflow/operators/python.py", line 238, in execute
    return_value = self.execute_callable()
                   ^^^^^^^^^^^^^^^^^^^^^^^
  File "/home/airflow/.local/lib/python3.12/site-packages/airflow/operators/python.py", line 256, in execute_callable
    return runner.run(*self.op_args, **self.op_kwargs)
           ^^^^^^^^^^^^^^^^^^^^^^^^^^^^^^^^^^^^^^^^^^^
  File "/home/airflow/.local/lib/python3.12/site-packages/airflow/utils/operator_helpers.py", line 252, in run
    return self.func(*args, **kwargs)
           ^^^^^^^^^^^^^^^^^^^^^^^^^^
  File "/opt/airflow/dags/etl/extract.py", line 38, in extract_data
    with open('mock_data/day_ahead_prices.xml', 'r') as f:
         ^^^^^^^^^^^^^^^^^^^^^^^^^^^^^^^^^^^^^^^^^^^
FileNotFoundError: [Errno 2] No such file or directory: 'mock_data/day_ahead_prices.xml'
[2025-04-18T13:40:09.409+0000] {local_task_job_runner.py:266} INFO - Task exited with return code 1
[2025-04-18T13:40:09.701+0000] {taskinstance.py:3901} INFO - 0 downstream tasks scheduled from follow-on schedule check
[2025-04-18T13:40:09.713+0000] {local_task_job_runner.py:245} INFO - ::endgroup::
