[2025-04-18T13:27:42.032+0000] {local_task_job_runner.py:123} INFO - ::group::Pre task execution logs
[2025-04-18T13:27:58.863+0000] {taskinstance.py:2614} INFO - Dependencies all met for dep_context=non-requeueable deps ti=<TaskInstance: entsoe_etl_germany.extract_data scheduled__2024-02-19T00:00:00+00:00 [queued]>
[2025-04-18T13:27:59.827+0000] {taskinstance.py:2614} INFO - Dependencies all met for dep_context=requeueable deps ti=<TaskInstance: entsoe_etl_germany.extract_data scheduled__2024-02-19T00:00:00+00:00 [queued]>
[2025-04-18T13:27:59.848+0000] {taskinstance.py:2867} INFO - Starting attempt 1 of 2
[2025-04-18T13:28:01.017+0000] {taskinstance.py:2890} INFO - Executing <Task(PythonOperator): extract_data> on 2024-02-19 00:00:00+00:00
[2025-04-18T13:28:02.220+0000] {warnings.py:112} WARNING - /home/***/.local/lib/python3.12/site-packages/***/task/task_runner/standard_task_runner.py:70: DeprecationWarning: This process (pid=109) is multi-threaded, use of fork() may lead to deadlocks in the child.
  pid = os.fork()

[2025-04-18T13:28:02.282+0000] {standard_task_runner.py:72} INFO - Started process 135 to run task
[2025-04-18T13:28:02.259+0000] {standard_task_runner.py:104} INFO - Running: ['***', 'tasks', 'run', 'entsoe_etl_germany', 'extract_data', 'scheduled__2024-02-19T00:00:00+00:00', '--job-id', '683', '--raw', '--subdir', 'DAGS_FOLDER/entsoe_germany_dag.py', '--cfg-path', '/tmp/tmpj9bzxu7h']
[2025-04-18T13:28:02.384+0000] {standard_task_runner.py:105} INFO - Job 683: Subtask extract_data
[2025-04-18T13:28:05.510+0000] {task_command.py:467} INFO - Running <TaskInstance: entsoe_etl_germany.extract_data scheduled__2024-02-19T00:00:00+00:00 [running]> on host 4d82f98476de
[2025-04-18T13:28:07.222+0000] {taskinstance.py:3134} INFO - Exporting env vars: AIRFLOW_CTX_DAG_OWNER='***' AIRFLOW_CTX_DAG_ID='entsoe_etl_germany' AIRFLOW_CTX_TASK_ID='extract_data' AIRFLOW_CTX_EXECUTION_DATE='2024-02-19T00:00:00+00:00' AIRFLOW_CTX_TRY_NUMBER='1' AIRFLOW_CTX_DAG_RUN_ID='scheduled__2024-02-19T00:00:00+00:00'
[2025-04-18T13:28:07.296+0000] {logging_mixin.py:190} INFO - Task instance is in running state
[2025-04-18T13:28:07.306+0000] {logging_mixin.py:190} INFO -  Previous state of the Task instance: queued
[2025-04-18T13:28:07.312+0000] {logging_mixin.py:190} INFO - Current task name:extract_data state:running start_date:2025-04-18 13:27:58.882842+00:00
[2025-04-18T13:28:07.315+0000] {logging_mixin.py:190} INFO - Dag name:entsoe_etl_germany and current dag run status:running
[2025-04-18T13:28:07.324+0000] {taskinstance.py:732} INFO - ::endgroup::
[2025-04-18T13:28:07.398+0000] {taskinstance.py:3313} ERROR - Task failed with exception
Traceback (most recent call last):
  File "/home/airflow/.local/lib/python3.12/site-packages/airflow/models/taskinstance.py", line 768, in _execute_task
    result = _execute_callable(context=context, **execute_callable_kwargs)
             ^^^^^^^^^^^^^^^^^^^^^^^^^^^^^^^^^^^^^^^^^^^^^^^^^^^^^^^^^^^^^
  File "/home/airflow/.local/lib/python3.12/site-packages/airflow/models/taskinstance.py", line 734, in _execute_callable
    return ExecutionCallableRunner(
           ^^^^^^^^^^^^^^^^^^^^^^^^
  File "/home/airflow/.local/lib/python3.12/site-packages/airflow/utils/operator_helpers.py", line 252, in run
    return self.func(*args, **kwargs)
           ^^^^^^^^^^^^^^^^^^^^^^^^^^
  File "/home/airflow/.local/lib/python3.12/site-packages/airflow/models/baseoperator.py", line 424, in wrapper
    return func(self, *args, **kwargs)
           ^^^^^^^^^^^^^^^^^^^^^^^^^^^
  File "/home/airflow/.local/lib/python3.12/site-packages/airflow/operators/python.py", line 238, in execute
    return_value = self.execute_callable()
                   ^^^^^^^^^^^^^^^^^^^^^^^
  File "/home/airflow/.local/lib/python3.12/site-packages/airflow/operators/python.py", line 256, in execute_callable
    return runner.run(*self.op_args, **self.op_kwargs)
           ^^^^^^^^^^^^^^^^^^^^^^^^^^^^^^^^^^^^^^^^^^^
  File "/home/airflow/.local/lib/python3.12/site-packages/airflow/utils/operator_helpers.py", line 252, in run
    return self.func(*args, **kwargs)
           ^^^^^^^^^^^^^^^^^^^^^^^^^^
  File "/opt/airflow/dags/etl/extract.py", line 38, in extract_data
    with open('mock_data/day_ahead_prices.xml', 'r') as f:
         ^^^^^^^^^^^^^^^^^^^^^^^^^^^^^^^^^^^^^^^^^^^
FileNotFoundError: [Errno 2] No such file or directory: 'mock_data/day_ahead_prices.xml'
[2025-04-18T13:28:07.891+0000] {logging_mixin.py:190} INFO - Task instance in failure state
[2025-04-18T13:28:07.905+0000] {logging_mixin.py:190} INFO - Task start:2025-04-18 13:27:58.882842+00:00 end:2025-04-18 13:28:07.870864+00:00 duration:8.988022
[2025-04-18T13:28:07.910+0000] {logging_mixin.py:190} INFO - Task:<Task(PythonOperator): extract_data> dag:<DAG: entsoe_etl_germany> dagrun:<DagRun entsoe_etl_germany @ 2024-02-19 00:00:00+00:00: scheduled__2024-02-19T00:00:00+00:00, state:running, queued_at: 2025-04-18 13:27:15.935536+00:00. externally triggered: False>
[2025-04-18T13:28:07.919+0000] {logging_mixin.py:190} INFO - Failure caused by [Errno 2] No such file or directory: 'mock_data/day_ahead_prices.xml'
[2025-04-18T13:28:07.934+0000] {taskinstance.py:1226} INFO - Marking task as UP_FOR_RETRY. dag_id=entsoe_etl_germany, task_id=extract_data, run_id=scheduled__2024-02-19T00:00:00+00:00, execution_date=20240219T000000, start_date=20250418T132758, end_date=20250418T132807
