[2025-04-18T13:27:38.867+0000] {local_task_job_runner.py:123} INFO - ::group::Pre task execution logs
[2025-04-18T13:27:53.700+0000] {taskinstance.py:2614} INFO - Dependencies all met for dep_context=non-requeueable deps ti=<TaskInstance: entsoe_etl_germany.extract_data scheduled__2024-02-18T00:00:00+00:00 [queued]>
[2025-04-18T13:27:53.874+0000] {taskinstance.py:2614} INFO - Dependencies all met for dep_context=requeueable deps ti=<TaskInstance: entsoe_etl_germany.extract_data scheduled__2024-02-18T00:00:00+00:00 [queued]>
[2025-04-18T13:27:53.904+0000] {taskinstance.py:2867} INFO - Starting attempt 1 of 2
[2025-04-18T13:27:54.256+0000] {taskinstance.py:2890} INFO - Executing <Task(PythonOperator): extract_data> on 2024-02-18 00:00:00+00:00
[2025-04-18T13:27:54.456+0000] {warnings.py:112} WARNING - /home/***/.local/lib/python3.12/site-packages/***/task/task_runner/standard_task_runner.py:70: DeprecationWarning: This process (pid=108) is multi-threaded, use of fork() may lead to deadlocks in the child.
  pid = os.fork()

[2025-04-18T13:27:54.535+0000] {standard_task_runner.py:72} INFO - Started process 131 to run task
[2025-04-18T13:27:54.511+0000] {standard_task_runner.py:104} INFO - Running: ['***', 'tasks', 'run', 'entsoe_etl_germany', 'extract_data', 'scheduled__2024-02-18T00:00:00+00:00', '--job-id', '681', '--raw', '--subdir', 'DAGS_FOLDER/entsoe_germany_dag.py', '--cfg-path', '/tmp/tmpj6yal9hl']
[2025-04-18T13:27:54.572+0000] {standard_task_runner.py:105} INFO - Job 681: Subtask extract_data
[2025-04-18T13:27:56.460+0000] {task_command.py:467} INFO - Running <TaskInstance: entsoe_etl_germany.extract_data scheduled__2024-02-18T00:00:00+00:00 [running]> on host 4d82f98476de
[2025-04-18T13:28:00.206+0000] {taskinstance.py:3134} INFO - Exporting env vars: AIRFLOW_CTX_DAG_OWNER='***' AIRFLOW_CTX_DAG_ID='entsoe_etl_germany' AIRFLOW_CTX_TASK_ID='extract_data' AIRFLOW_CTX_EXECUTION_DATE='2024-02-18T00:00:00+00:00' AIRFLOW_CTX_TRY_NUMBER='1' AIRFLOW_CTX_DAG_RUN_ID='scheduled__2024-02-18T00:00:00+00:00'
[2025-04-18T13:28:00.300+0000] {logging_mixin.py:190} INFO - Task instance is in running state
[2025-04-18T13:28:00.322+0000] {logging_mixin.py:190} INFO -  Previous state of the Task instance: queued
[2025-04-18T13:28:00.331+0000] {logging_mixin.py:190} INFO - Current task name:extract_data state:running start_date:2025-04-18 13:27:53.724468+00:00
[2025-04-18T13:28:00.335+0000] {logging_mixin.py:190} INFO - Dag name:entsoe_etl_germany and current dag run status:running
[2025-04-18T13:28:00.338+0000] {taskinstance.py:732} INFO - ::endgroup::
[2025-04-18T13:28:00.380+0000] {taskinstance.py:3313} ERROR - Task failed with exception
Traceback (most recent call last):
  File "/home/airflow/.local/lib/python3.12/site-packages/airflow/models/taskinstance.py", line 768, in _execute_task
    result = _execute_callable(context=context, **execute_callable_kwargs)
             ^^^^^^^^^^^^^^^^^^^^^^^^^^^^^^^^^^^^^^^^^^^^^^^^^^^^^^^^^^^^^
  File "/home/airflow/.local/lib/python3.12/site-packages/airflow/models/taskinstance.py", line 734, in _execute_callable
    return ExecutionCallableRunner(
           ^^^^^^^^^^^^^^^^^^^^^^^^
  File "/home/airflow/.local/lib/python3.12/site-packages/airflow/utils/operator_helpers.py", line 252, in run
    return self.func(*args, **kwargs)
           ^^^^^^^^^^^^^^^^^^^^^^^^^^
  File "/home/airflow/.local/lib/python3.12/site-packages/airflow/models/baseoperator.py", line 424, in wrapper
    return func(self, *args, **kwargs)
           ^^^^^^^^^^^^^^^^^^^^^^^^^^^
  File "/home/airflow/.local/lib/python3.12/site-packages/airflow/operators/python.py", line 238, in execute
    return_value = self.execute_callable()
                   ^^^^^^^^^^^^^^^^^^^^^^^
  File "/home/airflow/.local/lib/python3.12/site-packages/airflow/operators/python.py", line 256, in execute_callable
    return runner.run(*self.op_args, **self.op_kwargs)
           ^^^^^^^^^^^^^^^^^^^^^^^^^^^^^^^^^^^^^^^^^^^
  File "/home/airflow/.local/lib/python3.12/site-packages/airflow/utils/operator_helpers.py", line 252, in run
    return self.func(*args, **kwargs)
           ^^^^^^^^^^^^^^^^^^^^^^^^^^
  File "/opt/airflow/dags/etl/extract.py", line 38, in extract_data
    with open('mock_data/day_ahead_prices.xml', 'r') as f:
         ^^^^^^^^^^^^^^^^^^^^^^^^^^^^^^^^^^^^^^^^^^^
FileNotFoundError: [Errno 2] No such file or directory: 'mock_data/day_ahead_prices.xml'
[2025-04-18T13:28:00.492+0000] {job.py:229} INFO - Heartbeat recovered after 22.05 seconds
[2025-04-18T13:28:04.159+0000] {local_task_job_runner.py:266} INFO - Task exited with return code -9. For more information, see https://***.apache.org/docs/apache-***/stable/troubleshooting.html#LocalTaskJob-killed
[2025-04-18T13:28:04.649+0000] {standard_task_runner.py:217} INFO - Process not found (most likely exited), stop collecting metrics
[2025-04-18T13:28:05.329+0000] {taskinstance.py:3901} INFO - 0 downstream tasks scheduled from follow-on schedule check
[2025-04-18T13:28:05.386+0000] {local_task_job_runner.py:245} INFO - ::endgroup::
