[2025-04-18T13:26:57.869+0000] {local_task_job_runner.py:123} INFO - ::group::Pre task execution logs
[2025-04-18T13:26:58.446+0000] {taskinstance.py:2614} INFO - Dependencies all met for dep_context=non-requeueable deps ti=<TaskInstance: entsoe_etl_germany.extract_data scheduled__2024-02-03T00:00:00+00:00 [queued]>
[2025-04-18T13:26:58.724+0000] {taskinstance.py:2614} INFO - Dependencies all met for dep_context=requeueable deps ti=<TaskInstance: entsoe_etl_germany.extract_data scheduled__2024-02-03T00:00:00+00:00 [queued]>
[2025-04-18T13:26:58.770+0000] {taskinstance.py:2867} INFO - Starting attempt 2 of 2
[2025-04-18T13:26:59.023+0000] {taskinstance.py:2890} INFO - Executing <Task(PythonOperator): extract_data> on 2024-02-03 00:00:00+00:00
[2025-04-18T13:26:59.127+0000] {warnings.py:112} WARNING - /home/***/.local/lib/python3.12/site-packages/***/task/task_runner/standard_task_runner.py:70: DeprecationWarning: This process (pid=70) is multi-threaded, use of fork() may lead to deadlocks in the child.
  pid = os.fork()

[2025-04-18T13:26:59.152+0000] {standard_task_runner.py:72} INFO - Started process 99 to run task
[2025-04-18T13:26:59.167+0000] {standard_task_runner.py:104} INFO - Running: ['***', 'tasks', 'run', 'entsoe_etl_germany', 'extract_data', 'scheduled__2024-02-03T00:00:00+00:00', '--job-id', '677', '--raw', '--subdir', 'DAGS_FOLDER/entsoe_germany_dag.py', '--cfg-path', '/tmp/tmp9zofjwwc']
[2025-04-18T13:26:59.218+0000] {standard_task_runner.py:105} INFO - Job 677: Subtask extract_data
[2025-04-18T13:27:12.629+0000] {task_command.py:467} INFO - Running <TaskInstance: entsoe_etl_germany.extract_data scheduled__2024-02-03T00:00:00+00:00 [running]> on host 4d82f98476de
[2025-04-18T13:27:13.522+0000] {taskinstance.py:3134} INFO - Exporting env vars: AIRFLOW_CTX_DAG_OWNER='***' AIRFLOW_CTX_DAG_ID='entsoe_etl_germany' AIRFLOW_CTX_TASK_ID='extract_data' AIRFLOW_CTX_EXECUTION_DATE='2024-02-03T00:00:00+00:00' AIRFLOW_CTX_TRY_NUMBER='2' AIRFLOW_CTX_DAG_RUN_ID='scheduled__2024-02-03T00:00:00+00:00'
[2025-04-18T13:27:13.552+0000] {logging_mixin.py:190} INFO - Task instance is in running state
[2025-04-18T13:27:13.554+0000] {logging_mixin.py:190} INFO -  Previous state of the Task instance: queued
[2025-04-18T13:27:13.555+0000] {logging_mixin.py:190} INFO - Current task name:extract_data state:running start_date:2025-04-18 13:26:58.480017+00:00
[2025-04-18T13:27:13.556+0000] {logging_mixin.py:190} INFO - Dag name:entsoe_etl_germany and current dag run status:running
[2025-04-18T13:27:13.560+0000] {taskinstance.py:732} INFO - ::endgroup::
[2025-04-18T13:27:13.585+0000] {taskinstance.py:3313} ERROR - Task failed with exception
Traceback (most recent call last):
  File "/home/airflow/.local/lib/python3.12/site-packages/airflow/models/taskinstance.py", line 768, in _execute_task
    result = _execute_callable(context=context, **execute_callable_kwargs)
             ^^^^^^^^^^^^^^^^^^^^^^^^^^^^^^^^^^^^^^^^^^^^^^^^^^^^^^^^^^^^^
  File "/home/airflow/.local/lib/python3.12/site-packages/airflow/models/taskinstance.py", line 734, in _execute_callable
    return ExecutionCallableRunner(
           ^^^^^^^^^^^^^^^^^^^^^^^^
  File "/home/airflow/.local/lib/python3.12/site-packages/airflow/utils/operator_helpers.py", line 252, in run
    return self.func(*args, **kwargs)
           ^^^^^^^^^^^^^^^^^^^^^^^^^^
  File "/home/airflow/.local/lib/python3.12/site-packages/airflow/models/baseoperator.py", line 424, in wrapper
    return func(self, *args, **kwargs)
           ^^^^^^^^^^^^^^^^^^^^^^^^^^^
  File "/home/airflow/.local/lib/python3.12/site-packages/airflow/operators/python.py", line 238, in execute
    return_value = self.execute_callable()
                   ^^^^^^^^^^^^^^^^^^^^^^^
  File "/home/airflow/.local/lib/python3.12/site-packages/airflow/operators/python.py", line 256, in execute_callable
    return runner.run(*self.op_args, **self.op_kwargs)
           ^^^^^^^^^^^^^^^^^^^^^^^^^^^^^^^^^^^^^^^^^^^
  File "/home/airflow/.local/lib/python3.12/site-packages/airflow/utils/operator_helpers.py", line 252, in run
    return self.func(*args, **kwargs)
           ^^^^^^^^^^^^^^^^^^^^^^^^^^
  File "/opt/airflow/dags/etl/extract.py", line 38, in extract_data
    with open('mock_data/day_ahead_prices.xml', 'r') as f:
         ^^^^^^^^^^^^^^^^^^^^^^^^^^^^^^^^^^^^^^^^^^^
FileNotFoundError: [Errno 2] No such file or directory: 'mock_data/day_ahead_prices.xml'
[2025-04-18T13:27:13.898+0000] {logging_mixin.py:190} INFO - Task instance in failure state
[2025-04-18T13:27:13.902+0000] {logging_mixin.py:190} INFO - Task start:2025-04-18 13:26:58.480017+00:00 end:2025-04-18 13:27:13.885349+00:00 duration:15.405332
[2025-04-18T13:27:13.905+0000] {logging_mixin.py:190} INFO - Task:<Task(PythonOperator): extract_data> dag:<DAG: entsoe_etl_germany> dagrun:<DagRun entsoe_etl_germany @ 2024-02-03 00:00:00+00:00: scheduled__2024-02-03T00:00:00+00:00, state:running, queued_at: 2025-04-18 13:17:18.164470+00:00. externally triggered: False>
[2025-04-18T13:27:13.907+0000] {logging_mixin.py:190} INFO - Failure caused by [Errno 2] No such file or directory: 'mock_data/day_ahead_prices.xml'
[2025-04-18T13:27:13.914+0000] {taskinstance.py:1226} INFO - Marking task as FAILED. dag_id=entsoe_etl_germany, task_id=extract_data, run_id=scheduled__2024-02-03T00:00:00+00:00, execution_date=20240203T000000, start_date=20250418T132658, end_date=20250418T132713
[2025-04-18T13:27:14.392+0000] {taskinstance.py:341} INFO - ::group::Post task execution logs
[2025-04-18T13:27:14.400+0000] {standard_task_runner.py:124} ERROR - Failed to execute job 677 for task extract_data ([Errno 2] No such file or directory: 'mock_data/day_ahead_prices.xml'; 99)
Traceback (most recent call last):
  File "/home/airflow/.local/lib/python3.12/site-packages/airflow/task/task_runner/standard_task_runner.py", line 117, in _start_by_fork
    ret = args.func(args, dag=self.dag)
          ^^^^^^^^^^^^^^^^^^^^^^^^^^^^^
  File "/home/airflow/.local/lib/python3.12/site-packages/airflow/cli/cli_config.py", line 49, in command
    return func(*args, **kwargs)
           ^^^^^^^^^^^^^^^^^^^^^
  File "/home/airflow/.local/lib/python3.12/site-packages/airflow/utils/cli.py", line 116, in wrapper
    return f(*args, **kwargs)
           ^^^^^^^^^^^^^^^^^^
  File "/home/airflow/.local/lib/python3.12/site-packages/airflow/cli/commands/task_command.py", line 483, in task_run
    task_return_code = _run_task_by_selected_method(args, _dag, ti)
                       ^^^^^^^^^^^^^^^^^^^^^^^^^^^^^^^^^^^^^^^^^^^^
  File "/home/airflow/.local/lib/python3.12/site-packages/airflow/cli/commands/task_command.py", line 256, in _run_task_by_selected_method
    return _run_raw_task(args, ti)
           ^^^^^^^^^^^^^^^^^^^^^^^
  File "/home/airflow/.local/lib/python3.12/site-packages/airflow/cli/commands/task_command.py", line 341, in _run_raw_task
    return ti._run_raw_task(
           ^^^^^^^^^^^^^^^^^
  File "/home/airflow/.local/lib/python3.12/site-packages/airflow/utils/session.py", line 97, in wrapper
    return func(*args, session=session, **kwargs)
           ^^^^^^^^^^^^^^^^^^^^^^^^^^^^^^^^^^^^^^
  File "/home/airflow/.local/lib/python3.12/site-packages/airflow/models/taskinstance.py", line 3006, in _run_raw_task
    return _run_raw_task(
           ^^^^^^^^^^^^^^
  File "/home/airflow/.local/lib/python3.12/site-packages/airflow/models/taskinstance.py", line 274, in _run_raw_task
    TaskInstance._execute_task_with_callbacks(
  File "/home/airflow/.local/lib/python3.12/site-packages/airflow/models/taskinstance.py", line 3161, in _execute_task_with_callbacks
    result = self._execute_task(context, task_orig)
             ^^^^^^^^^^^^^^^^^^^^^^^^^^^^^^^^^^^^^^
  File "/home/airflow/.local/lib/python3.12/site-packages/airflow/models/taskinstance.py", line 3185, in _execute_task
    return _execute_task(self, context, task_orig)
           ^^^^^^^^^^^^^^^^^^^^^^^^^^^^^^^^^^^^^^^
  File "/home/airflow/.local/lib/python3.12/site-packages/airflow/models/taskinstance.py", line 768, in _execute_task
    result = _execute_callable(context=context, **execute_callable_kwargs)
             ^^^^^^^^^^^^^^^^^^^^^^^^^^^^^^^^^^^^^^^^^^^^^^^^^^^^^^^^^^^^^
  File "/home/airflow/.local/lib/python3.12/site-packages/airflow/models/taskinstance.py", line 734, in _execute_callable
    return ExecutionCallableRunner(
           ^^^^^^^^^^^^^^^^^^^^^^^^
  File "/home/airflow/.local/lib/python3.12/site-packages/airflow/utils/operator_helpers.py", line 252, in run
    return self.func(*args, **kwargs)
           ^^^^^^^^^^^^^^^^^^^^^^^^^^
  File "/home/airflow/.local/lib/python3.12/site-packages/airflow/models/baseoperator.py", line 424, in wrapper
    return func(self, *args, **kwargs)
           ^^^^^^^^^^^^^^^^^^^^^^^^^^^
  File "/home/airflow/.local/lib/python3.12/site-packages/airflow/operators/python.py", line 238, in execute
    return_value = self.execute_callable()
                   ^^^^^^^^^^^^^^^^^^^^^^^
  File "/home/airflow/.local/lib/python3.12/site-packages/airflow/operators/python.py", line 256, in execute_callable
    return runner.run(*self.op_args, **self.op_kwargs)
           ^^^^^^^^^^^^^^^^^^^^^^^^^^^^^^^^^^^^^^^^^^^
  File "/home/airflow/.local/lib/python3.12/site-packages/airflow/utils/operator_helpers.py", line 252, in run
    return self.func(*args, **kwargs)
           ^^^^^^^^^^^^^^^^^^^^^^^^^^
  File "/opt/airflow/dags/etl/extract.py", line 38, in extract_data
    with open('mock_data/day_ahead_prices.xml', 'r') as f:
         ^^^^^^^^^^^^^^^^^^^^^^^^^^^^^^^^^^^^^^^^^^^
FileNotFoundError: [Errno 2] No such file or directory: 'mock_data/day_ahead_prices.xml'
